Workbook

Sheet Backlog
A1: EPIC | B1: ID User Story | C1: Libellé User Story | D1: MVP | E1: Front_or_Back | F1: Module | G1: Dépend de (Parent) | H1: Type fonctionnel | I1: Pilier(s) | J1: Profil utilisateur | K1: Phrase méthode agile | L1: Point d'effort prestataire | M1: Point d'effort estimé MOA
A2: EPIC 1 – Gestion des données | B2: US1.1 | C2: Importer des données via fichier | D2: True | E2: Front-end | F2: Gestion des données & catalogue | H2: Acquisition | I2: Pilier 1 – Connaissance & Caractérisation | J2: Administrateur expert data | K2: En tant qu'administrateur expert data, je veux importer des données via fichier afin que la plateforme dispose de données fiables et homogènes. | L2: 12 | M2: 22
A3: EPIC 1 – Gestion des données | B3: US1.2 | C3: Connecter une API externe | D3: False | E3: Front-end | F3: Gestion des données & catalogue | H3: Acquisition | I3: Pilier 1 – Connaissance & Caractérisation | J3: Administrateur expert data | K3: En tant qu'administrateur expert data, je veux connecter une API externe afin d'alimenter la plateforme sans fichier.
A4: EPIC 1 – Gestion des données | B4: US1.3 | C4: Planifier des imports simples | D4: True | E4: Backend | F4: Gestion des données & catalogue | G4: US1.1 | H4: Acquisition | I4: Pilier 1 – Connaissance & Caractérisation | J4: Administrateur expert data | K4: En tant qu'administrateur expert data, je veux planifier des imports simples afin que les données soient actualisées automatiquement. | L4: =SUMIF('Besoins testables'!$D:$D,$A4,'Besoins testables'!$O:$O) -> 0
A5: EPIC 1 – Gestion des données | B5: US1.4 | C5: Normaliser les données | D5: True | E5: Backend | F5: Gestion des données & catalogue | G5: US1.1 | H5: Structuration | I5: Pilier 1 – Connaissance & Caractérisation | J5: Administrateur expert data | K5: En tant qu'administrateur expert data, je veux normaliser les données afin qu'elles soient homogènes et comparables. | L5: =SUMIF('Besoins testables'!$D:$D,$A5,'Besoins testables'!$O:$O) -> 0
A6: EPIC 1 – Gestion des données | B6: US1.5 | C6: Gérer les erreurs d'import | D6: True | E6: Front-end | F6: Gestion des données & catalogue | G6: US1.1 | H6: Acquisition | I6: Pilier 1 – Connaissance & Caractérisation | J6: Administrateur expert data | K6: En tant qu'administrateur expert data, je veux gérer les erreurs d'import afin de corriger les données rejetées efficacement. | L6: =SUMIF('Besoins testables'!$D:$D,$A6,'Besoins testables'!$O:$O) -> 0
A7: EPIC 1 – Gestion des données | B7: US1.6 | C7: Historiser les données | D7: True | E7: Backend | F7: Gestion des données & catalogue | G7: US1.1 | H7: Gouvernance | I7: Transverse (socle) | J7: Administrateur expert data | K7: En tant qu'administrateur expert data, je veux historiser les données afin de reconstituer leur évolution dans le temps. | L7: =SUMIF('Besoins testables'!$D:$D,$A7,'Besoins testables'!$O:$O) -> 0
A8: EPIC 1 – Gestion des données | B8: US1.7 | C8: Rejouer un traitement | D8: False | E8: Backend | F8: Gestion des données & catalogue | H8: Acquisition | I8: Pilier 1 – Connaissance & Caractérisation | J8: Administrateur expert data | K8: En tant qu'administrateur expert data, je veux rejouer un traitement afin de recalculer un jeu de données après correction.
A9: EPIC 1bis – Catalogage des données | B9: US1bis.1 | C9: Enregistrer un jeu de données dans le catalogue | D9: True | E9: Front-end | F9: Gestion des données & catalogue | G9: US1.2 | H9: Structuration | I9: Pilier 1 – Connaissance & Caractérisation | J9: Administrateur expert data | K9: En tant qu'administrateur expert data, je veux enregistrer un jeu de données dans le catalogue afin qu'il soit référencé et trouvable. | L9: =SUMIF('Besoins testables'!$D:$D,$A9,'Besoins testables'!$O:$O) -> 0
A10: EPIC 1bis – Catalogage des données | B10: US1bis.2 | C10: Associer des métadonnées à un jeu de données | D10: True | E10: Front-end | F10: Gestion des données & catalogue | G10: US1bis.1 | H10: Structuration | I10: Pilier 1 – Connaissance & Caractérisation | J10: Administrateur expert data | K10: En tant qu'administrateur expert data, je veux associer des métadonnées à un jeu de données afin d'en documenter l'origine et la structure. | L10: =SUMIF('Besoins testables'!$D:$D,$A10,'Besoins testables'!$O:$O) -> 0
A11: EPIC 1bis – Catalogage des données | B11: US1bis.3 | C11: Modifier les métadonnées d'un jeu de données | D11: False | E11: Front-end | F11: Gestion des données & catalogue | G11: US1bis.2 | H11: Structuration | I11: Pilier 1 – Connaissance & Caractérisation | J11: Administrateur expert data | K11: En tant qu'administrateur expert data, je veux modifier les métadonnées afin de maintenir le catalogue à jour.
A12: EPIC 1bis – Catalogage des données | B12: US1bis.4 | C12: Consulter les informations d'un jeu de données | D12: True | E12: Front-end | F12: Gestion des données & catalogue | H12: Structuration | I12: Pilier 1 – Connaissance & Caractérisation | J12: Administrateur expert data | K12: En tant qu'administrateur expert data, je veux consulter les informations d'un jeu de données afin d'en connaître le contenu et la source. | L12: =SUMIF('Besoins testables'!$D:$D,$A12,'Besoins testables'!$O:$O) -> 0
A13: EPIC 1bis – Catalogage des données | B13: US1bis.5 | C13: Rechercher un jeu de données dans le catalogue | D13: False | E13: Front-end | F13: Gestion des données & catalogue | H13: Structuration | I13: Pilier 1 – Connaissance & Caractérisation | J13: Administrateur expert data | K13: En tant qu'administrateur expert data, je veux rechercher un jeu de données afin de le retrouver rapidement dans le catalogue.
A14: EPIC 1bis – Catalogage des données | B14: US1bis.6 | C14: Filtrer les jeux de données selon des critères | D14: False | E14: Front-end | F14: Gestion des données & catalogue | H14: Structuration | I14: Pilier 1 – Connaissance & Caractérisation | J14: Administrateur expert data | K14: En tant qu'administrateur expert data, je veux filtrer les jeux de données selon des critères afin de restreindre la liste du catalogue.
A15: EPIC 1bis – Catalogage des données | B15: US1bis.7 | C15: Visualiser les relations entre indicateur et données sources | D15: True | E15: Front-end | F15: Gestion des données & catalogue | H15: Structuration | I15: Pilier 1 – Connaissance & Caractérisation | J15: Administrateur expert data | K15: En tant qu'administrateur expert data, je veux visualiser les relations entre un indicateur et ses données sources afin d'en comprendre la provenance. | L15: =SUMIF('Besoins testables'!$D:$D,$A15,'Besoins testables'!$O:$O) -> 0
A16: EPIC 1bis – Catalogage des données | B16: US1bis.8 | C16: Tracer les transformations appliquées à un jeu de données | D16: False | E16: Backend | F16: Gestion des données & catalogue | H16: Structuration | I16: Pilier 1 – Connaissance & Caractérisation | J16: Administrateur expert data | K16: En tant qu'administrateur expert data, je veux tracer les transformations appliquées à un jeu de données afin d'en garantir la reproductibilité.
A17: EPIC 1bis – Catalogage des données | B17: US1bis.9 | C17: Identifier une donnée comme source ou dérivée | D17: False | E17: Backend | F17: Gestion des données & catalogue | H17: Structuration | I17: Pilier 1 – Connaissance & Caractérisation | J17: Administrateur expert data | K17: En tant qu'administrateur expert data, je veux identifier une donnée comme source ou dérivée afin de clarifier sa place dans la chaîne.
A18: EPIC 1bis – Catalogage des données | B18: US1bis.10 | C18: Alimenter automatiquement le catalogue lors des imports | D18: True | E18: Backend | F18: Gestion des données & catalogue | G18: US1.1 ; US1bis.1 | H18: Acquisition | I18: Pilier 1 – Connaissance & Caractérisation | J18: Administrateur expert data | K18: En tant qu'administrateur expert data, je veux alimenter automatiquement le catalogue lors des imports afin d'éviter les saisies manuelles. | L18: =SUMIF('Besoins testables'!$D:$D,$A18,'Besoins testables'!$O:$O) -> 0
A19: EPIC 1bis – Catalogage des données | B19: US1bis.11 | C19: Relier un jeu de données à un traitement (ex : dbt) | D19: False | E19: Backend | F19: Gestion des données & catalogue | G19: US1bis.8 | H19: Structuration | I19: Pilier 1 – Connaissance & Caractérisation | J19: Administrateur expert data | K19: En tant qu'administrateur expert data, je veux relier un jeu de données à un traitement afin d'en retracer l'élaboration.
A20: EPIC 1bis – Catalogage des données | B20: US1bis.12 | C20: Enregistrer un indicateur comme donnée dérivée | D20: True | E20: Front-end | F20: Gestion des données & catalogue | G20: US3.5 | H20: Structuration | I20: Pilier 1 – Connaissance & Caractérisation | J20: Administrateur expert data | K20: En tant qu'administrateur expert data, je veux enregistrer un indicateur comme donnée dérivée afin qu'il soit identifié comme tel dans le catalogue. | L20: =SUMIF('Besoins testables'!$D:$D,$A20,'Besoins testables'!$O:$O) -> 0
A21: EPIC 1bis – Catalogage des données | B21: US1bis.13 | C21: Consulter les métadonnées d'un indicateur | D21: False | E21: Front-end | F21: Gestion des données & catalogue | H21: Structuration | I21: Pilier 1 – Connaissance & Caractérisation | J21: Administrateur expert data | K21: En tant qu'administrateur expert data, je veux consulter les métadonnées d'un indicateur afin d'en vérifier la définition et la méthode.
A22: EPIC 1bis – Catalogage des données | B22: US1bis.14 | C22: Ajouter un nouveau jeu de données sans modifier la structure | D22: False | E22: Backend | F22: Gestion des données & catalogue | H22: Structuration | I22: Pilier 1 – Connaissance & Caractérisation | J22: Administrateur expert data | K22: En tant qu'administrateur expert data, je veux ajouter un nouveau jeu de données sans modifier la structure afin d'étendre le catalogue à moindre coût.
A23: EPIC 1bis – Catalogage des données | B23: US1bis.15 | C23: Historiser les modifications des métadonnées | D23: False | E23: Backend | F23: Gestion des données & catalogue | H23: Structuration | I23: Pilier 1 – Connaissance & Caractérisation | J23: Administrateur expert data | K23: En tant qu'administrateur expert data, je veux historiser les modifications des métadonnées afin de tracer les évolutions du catalogue.
A24: EPIC 2 – Qualité des données | B24: US2.1 | C24: Détecter des valeurs aberrantes | D24: True | E24: Backend | F24: Suivi qualité & traçabilité | H24: Qualification | I24: Pilier 1 – Connaissance & Caractérisation (fondement) | J24: Administrateur expert data | K24: En tant qu'administrateur expert data, je veux détecter des valeurs aberrantes afin d'identifier les données à corriger. | L24: =SUMIF('Besoins testables'!$D:$D,$A24,'Besoins testables'!$O:$O) -> 0
A25: EPIC 2 – Qualité des données | B25: US2.2 | C25: Vérifier cohérence temporelle | D25: False | E25: Backend | F25: Suivi qualité & traçabilité | H25: Qualification | I25: Pilier 1 – Connaissance & Caractérisation (fondement) | J25: Administrateur expert data | K25: En tant qu'administrateur expert data, je veux vérifier la cohérence temporelle afin de détecter les incohérences de dates.
A26: EPIC 2 – Qualité des données | B26: US2.3 | C26: Vérifier cohérence spatiale | D26: False | E26: Backend | F26: Suivi qualité & traçabilité | H26: Qualification | I26: Pilier 1 – Connaissance & Caractérisation (fondement) | J26: Administrateur expert data | K26: En tant qu'administrateur expert data, je veux vérifier la cohérence spatiale afin de détecter les incohérences géographiques. | L26: =SUMIF('Besoins testables'!$D:$D,$A26,'Besoins testables'!$O:$O) -> 0
A27: EPIC 2 – Qualité des données | B27: US2.4 | C27: Calculer un taux de complétude | D27: True | E27: Backend | F27: Suivi qualité & traçabilité | H27: Qualification | I27: Pilier 1 – Connaissance & Caractérisation (fondement) | J27: Administrateur expert data | K27: En tant qu'administrateur expert data, je veux calculer un taux de complétude afin de mesurer la couverture des données. | L27: =SUMIF('Besoins testables'!$D:$D,$A27,'Besoins testables'!$O:$O) -> 0
A28: EPIC 2 – Qualité des données | B28: US2.5 | C28: Qualifier la fiabilité | D28: True | E28: Backend | F28: Suivi qualité & traçabilité | H28: Qualification | I28: Pilier 1 – Connaissance & Caractérisation (fondement) | J28: Administrateur expert data | K28: En tant qu'administrateur expert data, je veux qualifier la fiabilité afin d'évaluer la confiance à accorder aux données. | L28: =SUMIF('Besoins testables'!$D:$D,$A28,'Besoins testables'!$O:$O) -> 0
A29: EPIC 2 – Qualité des données | B29: US2.6 | C29: Associer des métadonnées | D29: True | E29: Front-end | F29: Suivi qualité & traçabilité | H29: Qualification | I29: Pilier 1 – Connaissance & Caractérisation (fondement) | J29: Administrateur expert data | K29: En tant qu'administrateur expert data, je veux associer des métadonnées de qualité afin de documenter les contrôles effectués. | L29: =SUMIF('Besoins testables'!$D:$D,$A29,'Besoins testables'!$O:$O) -> 0
A30: EPIC 2 – Qualité des données | B30: US2.7 | C30: Visualiser la qualité | D30: False | E30: Front-end | F30: Suivi qualité & traçabilité | H30: Qualification | I30: Pilier 1 – Connaissance & Caractérisation (fondement) | J30: Administrateur expert data | K30: En tant qu'administrateur expert data, je veux visualiser la qualité afin de repérer les jeux de données fiables.
A31: EPIC 3 – Référentiels | B31: US3.1 | C31: Gérer les bassins versants | D31: True | E31: Front-end | F31: Administration & profils | H31: Structuration | I31: Pilier 1 – Connaissance & Caractérisation | J31: Administrateur expert data | K31: En tant qu'administrateur expert data, je veux gérer les bassins versants afin de maintenir le référentiel à jour. | L31: =SUMIF('Besoins testables'!$D:$D,$A31,'Besoins testables'!$O:$O) -> 0
A32: EPIC 3 – Référentiels | B32: US3.2 | C32: Gérer les captages | D32: True | E32: Front-end | F32: Administration & profils | H32: Structuration | I32: Pilier 1 – Connaissance & Caractérisation | J32: Administrateur expert data | K32: En tant qu'administrateur expert data, je veux gérer les captages afin de maintenir le référentiel à jour. | L32: =SUMIF('Besoins testables'!$D:$D,$A32,'Besoins testables'!$O:$O) -> 0
A33: EPIC 3 – Référentiels | B33: US3.3 | C33: Gérer périmètres de protection | D33: False | E33: Front-end | F33: Administration & profils | H33: Structuration | I33: Pilier 1 – Connaissance & Caractérisation | J33: Administrateur expert data | K33: En tant qu'administrateur expert data, je veux gérer les périmètres de protection afin de les représenter sur la carte.
A34: EPIC 3 – Référentiels | B34: US3.4 | C34: Gérer la maille H3 | D34: True | E34: Front-end | F34: Administration & profils | H34: Structuration | I34: Pilier 1 – Connaissance & Caractérisation | J34: Administrateur expert data | K34: En tant qu'administrateur expert data, je veux gérer la maille H3 afin de garantir la cohérence des agrégations. | L34: =SUMIF('Besoins testables'!$D:$D,$A34,'Besoins testables'!$O:$O) -> 0
A35: EPIC 3 – Référentiels | B35: US3.5 | C35: Définir un indicateur | D35: True | E35: Front-end | F35: Administration & profils | H35: Structuration | I35: Pilier 1 – Connaissance & Caractérisation | J35: Administrateur expert data | K35: En tant qu'administrateur expert data, je veux définir un indicateur afin de le rendre calculable et affichable. | L35: =SUMIF('Besoins testables'!$D:$D,$A35,'Besoins testables'!$O:$O) -> 0
A36: EPIC 3 – Référentiels | B36: US3.6 | C36: Gérer les profils utilisateurs | D36: False | E36: Front-end | F36: Administration & profils | H36: Gouvernance | I36: Transverse (socle) | J36: Administrateur plateforme | K36: En tant qu'administrateur plateforme, je veux gérer les profils utilisateurs et leurs droits afin de contrôler les accès à la plateforme.
A37: EPIC 3 – Référentiels | B37: US3.7 | C37: Versionner les référentiels | D37: False | E37: Backend | F37: Administration & profils | H37: Structuration | I37: Pilier 1 – Connaissance & Caractérisation | J37: Administrateur expert data | K37: En tant qu'administrateur expert data, je veux versionner les référentiels afin de conserver l'historique de leurs évolutions.
A38: EPIC 4 – Calcul d'indicateurs | B38: US4.1 | C38: Calculer des indicateurs simples | D38: True | E38: Backend | F38: Gestion des données & catalogue | G38: US3.5 ; US4.7 ; US1bis.12 | H38: Exploitation | I38: Pilier 2 – Diagnostic & Analyse multicritère (+ Pilier 3) | J38: Administrateur expert data | K38: En tant qu'administrateur expert data, je veux calculer des indicateurs simples afin de produire des valeurs fiables. | L38: =SUMIF('Besoins testables'!$D:$D,$A38,'Besoins testables'!$O:$O) -> 0
A39: EPIC 4 – Calcul d'indicateurs | B39: US4.2 | C39: Agréger à l'échelle BV | D39: True | E39: Backend | F39: Gestion des données & catalogue | G39: US3.1 ; US4.1 | H39: Exploitation | I39: Pilier 2 – Diagnostic & Analyse multicritère (+ Pilier 3) | J39: Administrateur expert data | K39: En tant qu'administrateur expert data, je veux agréger à l'échelle du bassin versant afin de disposer de valeurs synthétiques. | L39: =SUMIF('Besoins testables'!$D:$D,$A39,'Besoins testables'!$O:$O) -> 0
A40: EPIC 4 – Calcul d'indicateurs | B40: US4.3 | C40: Agrégation temporelle | D40: True | E40: Backend | F40: Gestion des données & catalogue | G40: US1.6 ; US4.1 ; US6.24 | H40: Exploitation | I40: Pilier 2 – Diagnostic & Analyse multicritère (+ Pilier 3) | J40: Administrateur expert data | K40: En tant qu'administrateur expert data, je veux agréger les données dans le temps afin de produire des séries comparables. | L40: =SUMIF('Besoins testables'!$D:$D,$A40,'Besoins testables'!$O:$O) -> 0
...

Sheet Besoins testables
A1: Identifiant test | B1: Libellé scénario | C1: EPIC | D1: ID User Story | E1: Libellé User Story | F1: MVP | G1: Front_or_Back | H1: Module | I1: Dépend de (Parent) | J1: Type fonctionnel | K1: Pilier(s) | L1: Profil utilisateur | M1: Phrase méthode agile | N1: Scénario testable (complet) | O1: Point d'effort prestataire (1er niveau)
A2: US1.1-SC01 | B2: Import d'un fichier CSV conforme | C2: EPIC 1 – Gestion des données | D2: US1.1 | E2: Importer des données via fichier | F2: True | G2: Front-end | H2: Gestion des données & catalogue | J2: Acquisition | K2: Pilier 1 – Connaissance & Caractérisation | L2: Administrateur expert data | M2: En tant qu'administrateur expert data, je veux importer des données via fichier afin que la plateforme dispose de données fiables et homogènes. | N2: Étant donné un administrateur expert data connecté, Quand il importe un fichier CSV conforme au modèle attendu (en-têtes, types, unités), Alors les données sont enregistrées dans la plateforme, Et un message de succès indique le nombre de lignes chargées, Et le jeu de données apparaît dans le catalogue comme donnée source.
A3: US1.1-SC02 | B3: Import de données SIG (Shapefile/GeoJSON) | C3: EPIC 1 – Gestion des données | D3: US1.1 | E3: Importer des données via fichier | F3: True | G3: Front-end | H3: Gestion des données & catalogue | J3: Acquisition | K3: Pilier 1 – Connaissance & Caractérisation | L3: Administrateur expert data | M3: En tant qu'administrateur expert data, je veux importer des données via fichier afin que la plateforme dispose de données fiables et homogènes. | N3: Étant donné un fichier au format SIG (Shapefile, GeoJSON), Quand il est importé, Alors les géométries sont validées et converties dans le système de coordonnées de référence de la plateforme, Et les enregistrements invalides sont rejetés avec leur motif.
A4: US1.1-SC03 | B4: Détection des doublons à l'import | C4: EPIC 1 – Gestion des données | D4: US1.1 | E4: Importer des données via fichier | F4: True | G4: Front-end | H4: Gestion des données & catalogue | J4: Acquisition | K4: Pilier 1 – Connaissance & Caractérisation | L4: Administrateur expert data | M4: En tant qu'administrateur expert data, je veux importer des données via fichier afin que la plateforme dispose de données fiables et homogènes. | N4: Étant donné un fichier contenant des doublons (même identifiant captage et même date), Quand l'import est lancé, Alors les doublons sont détectés et signalés, Et aucun doublon n'est enregistré sans validation explicite de l'administrateur.
A5: US1.1-SC04 | B5: Exécution asynchrone d'un import volumineux | C5: EPIC 1 – Gestion des données | D5: US1.1 | E5: Importer des données via fichier | F5: True | G5: Front-end | H5: Gestion des données & catalogue | J5: Acquisition | K5: Pilier 1 – Connaissance & Caractérisation | L5: Administrateur expert data | M5: En tant qu'administrateur expert data, je veux importer des données via fichier afin que la plateforme dispose de données fiables et homogènes. | N5: Étant donné un import volumineux ou long, Quand l'import est lancé, Alors il s'exécute de manière asynchrone avec un statut visible (en cours / terminé / échec), sans bloquer les autres actions de l'administrateur.
A6: US1.1-SC05 | B6: Refus d'un fichier non conforme | C6: EPIC 1 – Gestion des données | D6: US1.1 | E6: Importer des données via fichier | F6: True | G6: Front-end | H6: Gestion des données & catalogue | J6: Acquisition | K6: Pilier 1 – Connaissance & Caractérisation | L6: Administrateur expert data | M6: En tant qu'administrateur expert data, je veux importer des données via fichier afin que la plateforme dispose de données fiables et homogènes. | N6: Étant donné un fichier non conforme (extension non supportée, colonnes obligatoires manquantes), Quand l'administrateur tente l'import, Alors l'import est refusée et un message d'erreur explicite liste les anomalies détectées.
A7: US1.3-SC01 | B7: Planification d'imports automatiques | C7: EPIC 1 – Gestion des données | D7: US1.3 | E7: Planifier des imports simples | F7: True | G7: Backend | H7: Gestion des données & catalogue | I7: US1.1 | J7: Acquisition | K7: Pilier 1 – Connaissance & Caractérisation | L7: Administrateur expert data | M7: En tant qu'administrateur expert data, je veux planifier des imports simples afin que les données soient actualisées automatiquement. | N7: Étant donné une source de données fichier, Quand l'administrateur définit une planification (fréquence journalière, hebdomadaire, mensuelle, heure d'exécution), Alors l'import est exécuté automatiquement à l'échéance prévue, Et chaque exécution est tracée (date, heure, source, résultat, volumétrie). - Quand un import planifié échoue, Alors son statut passe à « échec », l'événement est journalisé avec le motif, Et les exécutions suivantes restent programmées. - Quand la planification est modifiée ou supprimée, Alors seules les nouvelles exécutions respectent la configuration courante, les exécutions déjà tracées restant inchangées. - Quand deux imports planifiés se chevauchent, Alors le système les sérialise ou refuse le chevauchement sans perte de données.
A8: US1.3-SC02 | B8: Échec d'un import planifié sans source | C8: EPIC 1 – Gestion des données | D8: US1.3 | E8: Planifier des imports simples | F8: True | G8: Backend | H8: Gestion des données & catalogue | I8: US1.1 | J8: Acquisition | K8: Pilier 1 – Connaissance & Caractérisation | L8: Administrateur expert data | M8: En tant qu'administrateur expert data, je veux planifier des imports simples afin que les données soient actualisées automatiquement. | N8: Étant donné un import planifié sans fichier source disponible à l'échéance, Alors l'exécution est signalée en échec avec un motif explicite, Et aucune donnée partielle ou vide n'est enregistrée.
A9: US1.4-SC01 | B9: Normalisation de données hétérogènes | C9: EPIC 1 – Gestion des données | D9: US1.4 | E9: Normaliser les données | F9: True | G9: Backend | H9: Gestion des données & catalogue | I9: US1.1 | J9: Structuration | K9: Pilier 1 – Connaissance & Caractérisation | L9: Administrateur expert data | M9: En tant qu'administrateur expert data, je veux normaliser les données afin qu'elles soient homogènes et comparables. | N9: Étant donné des données brutes hétérogènes (unités, formats de date, nomenclatures), Quand elles sont intégrées, Alors elles sont converties selon les règles de normalisation de la plateforme (unités de référence, dates ISO 8601, identifiants des référentiels), Et chaque transformation est documentée et tracée.
A10: US1.4-SC02 | B10: Rattachement à un objet du référentiel | C10: EPIC 1 – Gestion des données | D10: US1.4 | E10: Normaliser les données | F10: True | G10: Backend | H10: Gestion des données & catalogue | I10: US1.1 | J10: Structuration | K10: Pilier 1 – Connaissance & Caractérisation | L10: Administrateur expert data | M10: En tant qu'administrateur expert data, je veux normaliser les données afin qu'elles soient homogènes et comparables. | N10: Étant donné une valeur référant à un captage ou un BVAEP, Quand la normalisation s'exécute, Alors la valeur est rattachée à l'objet correspondant du référentiel, Et toute valeur non rattachable est signalée en anomalie sans bloquer le reste du jeu.
A11: US1.4-SC03 | B11: Rejet d'une valeur hors plage | C11: EPIC 1 – Gestion des données | D11: US1.4 | E11: Normaliser les données | F11: True | G11: Backend | H11: Gestion des données & catalogue | I11: US1.1 | J11: Structuration | K11: Pilier 1 – Connaissance & Caractérisation | L11: Administrateur expert data | M11: En tant qu'administrateur expert data, je veux normaliser les données afin qu'elles soient homogènes et comparables. | N11: Étant donné une valeur numérique hors plage ou un format inattendu, Quand la normalisation échoue pour cette ligne, Alors la ligne est marquée « non normalisée », Et le reste du jeu est traité sans blocage global. - Quand aucune règle de normalisation n'existe pour une colonne obligatoire, Alors l'import est refusée avec un message renvoyant vers la configuration de la source. - Quand un jeu de données normalisé est réimporté, Alors les mêmes règles produisent les mêmes valeurs (reproductibilité de la normalisation).
A12: US1.5-SC01 | B12: Rapport d'erreurs avec rejet partiel | C12: EPIC 1 – Gestion des données | D12: US1.5 | E12: Gérer les erreurs d'import | F12: True | G12: Front-end | H12: Gestion des données & catalogue | I12: US1.1 | J12: Acquisition | K12: Pilier 1 – Connaissance & Caractérisation | L12: Administrateur expert data | M12: En tant qu'administrateur expert data, je veux gérer les erreurs d'import afin de corriger les données rejetées efficacement. | N12: Étant donné un fichier CSV contenant 3 lignes invalides sur 100, Quand l'import est exécuté, Alors un rapport d'erreurs est généré listant les 3 lignes avec leur motif de rejet, Et les 97 lignes valides sont enregistrées. - Quand l'administrateur ouvre le rapport d'erreurs, Alors il voit pour chaque erreur le numéro de ligne, la valeur en cause et le motif (type, plage, rattachement référentiel, doublon).
A13: US1.5-SC02 | B13: Refus global d'un import invalide | C13: EPIC 1 – Gestion des données | D13: US1.5 | E13: Gérer les erreurs d'import | F13: True | G13: Front-end | H13: Gestion des données & catalogue | I13: US1.1 | J13: Acquisition | K13: Pilier 1 – Connaissance & Caractérisation | L13: Administrateur expert data | M13: En tant qu'administrateur expert data, je veux gérer les erreurs d'import afin de corriger les données rejetées efficacement. | N13: Étant donné un fichier entièrement invalide, Quand aucun enregistrement ne passe les contrôles, Alors l'import est refusée dans sa globalité et aucun enregistrement n'est créé. - Quand un import se termine avec des rejets, Alors un message d'alerte informe l'administrateur du nombre d'enregistrements rejetés, avec un lien vers le rapport d'erreurs.
A14: US1.5-SC03 | B14: Relance d'import après correction | C14: EPIC 1 – Gestion des données | D14: US1.5 | E14: Gérer les erreurs d'import | F14: True | G14: Front-end | H14: Gestion des données & catalogue | I14: US1.1 | J14: Acquisition | K14: Pilier 1 – Connaissance & Caractérisation | L14: Administrateur expert data | M14: En tant qu'administrateur expert data, je veux gérer les erreurs d'import afin de corriger les données rejetées efficacement. | N14: Étant donné un fichier corrigé après un rejet, Quand l'administrateur relance l'import, Alors seules les nouvelles anomalies sont signalées, les lignes précédemment corrigées n'apparaissant plus dans le rapport.
A15: US1.6-SC01 | B15: Création de versions historisées | C15: EPIC 1 – Gestion des données | D15: US1.6 | E15: Historiser les données | F15: True | G15: Backend | H15: Gestion des données & catalogue | I15: US1.1 | J15: Gouvernance | K15: Transverse (socle) | L15: Administrateur expert data | M15: En tant qu'administrateur expert data, je veux historiser les données afin de reconstituer leur évolution dans le temps. | N15: Étant donné un jeu de données déjà importé, Quand un nouvel import met à jour ce jeu, Alors une nouvelle version est créée, Et les versions antérieures sont intégralement conservées et consultables. - Quand une donnée est modifiée ou supprimée, Alors l'historisation conserve l'intégralité des versions antérieures : aucune valeur écrasée n'est perdue.
A16: US1.6-SC02 | B16: Reconstitution d'un état à une date | C16: EPIC 1 – Gestion des données | D16: US1.6 | E16: Historiser les données | F16: True | G16: Backend | H16: Gestion des données & catalogue | I16: US1.1 | J16: Gouvernance | K16: Transverse (socle) | L16: Administrateur expert data | M16: En tant qu'administrateur expert data, je veux historiser les données afin de reconstituer leur évolution dans le temps. | N16: Étant donné une date de référence, Quand l'administrateur interroge l'historique, Alors il peut reconstituer l'état du jeu de données tel qu'il existait à cette date. - Quand une nouvelle version est enregistrée, Alors son horodatage, sa source et le traitement d'origine sont tracés. - Quand une opération de réécriture est demandée, Alors aucune donnée existante n'est écrasée sans création préalable d'une nouvelle version (aucune suppression destructive). ### EPIC 1bis — Catalogage des données
A17: US1bis.1-SC01 | B17: Enregistrement d'un jeu dans le catalogue | C17: EPIC 1bis – Catalogage des données | D17: US1bis.1 | E17: Enregistrer un jeu de données dans le catalogue | F17: True | G17: Front-end | H17: Gestion des données & catalogue | I17: US1.2 | J17: Structuration | K17: Pilier 1 – Connaissance & Caractérisation | L17: Administrateur expert data | M17: En tant qu'administrateur expert data, je veux enregistrer un jeu de données dans le catalogue afin qu'il soit référencé et trouvable. | N17: Étant donné un jeu de données intégré dans la plateforme, Quand l'administrateur l'enregistre dans le catalogue, Alors il reçoit un identifiant unique de catalogue, Et il devient visible et trouvable dans la liste du catalogue. - Quand un jeu de données est enregistré, Alors les champs obligatoires suivants sont renseignés et validés : nom, fournisseur, date de mise à jour, licence ; l'enregistrement est refusé tant qu'ils sont manquants.
A18: US1bis.1-SC02 | B18: Refus d'un identifiant déjà utilisé | C18: EPIC 1bis – Catalogage des données | D18: US1bis.1 | E18: Enregistrer un jeu de données dans le catalogue | F18: True | G18: Front-end | H18: Gestion des données & catalogue | I18: US1.2 | J18: Structuration | K18: Pilier 1 – Connaissance & Caractérisation | L18: Administrateur expert data | M18: En tant qu'administrateur expert data, je veux enregistrer un jeu de données dans le catalogue afin qu'il soit référencé et trouvable. | N18: Étant donné un identifiant de catalogue déjà utilisé, Quand l'administrateur tente d'enregistrer un autre jeu avec cet identifiant, Alors l'enregistrement est refusée et un message explicite s'affiche. - Quand un jeu de données enregistré est mis à jour (nouvel import), Alors la fiche du catalogue reste liée à la version courante du jeu.
... A22: US1bis.2-SC03 | B22: Refus d'une licence non autorisée | C22: EPIC 1bis – Catalogage des données | D22: US1bis.2 | E22: Associer des métadonnées à un jeu de données | F22: True | G22: Front-end | H22: Gestion des données & catalogue | I22: US1bis.1 | J22: Structuration | K22: Pilier 1 – Connaissance & Caractérisation | L22: Administrateur expert data | M22: En tant qu'administrateur expert data, je veux associer des métadonnées à un jeu de données afin d'en documenter l'origine et la structure. | N22: Étant donné une licence non autorisée ou une date de mise à jour future, Quand l'enregistrement est tenté, Alors il est refusé avec un message d'erreur explicite.
A23: US1bis.4-SC01 | B23: Consultation d'une fiche de jeu de données | C23: EPIC 1bis – Catalogage des données | D23: US1bis.4 | E23: Consulter les informations d'un jeu de données | F23: True | G23: Front-end | H23: Gestion des données & catalogue | J23: Structuration | K23: Pilier 1 – Connaissance & Caractérisation | L23: Administrateur expert data | M23: En tant qu'administrateur expert data, je veux consulter les informations d'un jeu de données afin d'en connaître le contenu et la source. | N23: Étant donné un jeu de données du catalogue, Quand l'utilisateur ouvre sa fiche, Alors il voit son nom, son fournisseur, sa date de mise à jour, sa licence, sa couverture spatiale et temporelle, et son type (donnée source ou donnée dérivée). - Quand l'utilisateur consulte la fiche, Alors il voit la structure du jeu (champs, types, unités) et, si disponible, un aperçu du contenu.
A24: US1bis.4-SC02 | B24: Fiche d'un jeu dérivé | C24: EPIC 1bis – Catalogage des données | D24: US1bis.4 | E24: Consulter les informations d'un jeu de données | F24: True | G24: Front-end | H24: Gestion des données & catalogue | J24: Structuration | K24: Pilier 1 – Connaissance & Caractérisation | L24: Administrateur expert data | M24: En tant qu'administrateur expert data, je veux consulter les informations d'un jeu de données afin d'en connaître le contenu et la source. | N24: Étant donné un jeu de données dérivé, Quand sa fiche est consultée, Alors elle affiche les données sources et les traitements dont il provient.
A25: US1bis.4-SC03 | B25: Affichage d'une licence non renseignée | C25: EPIC 1bis – Catalogage des données | D25: US1bis.4 | E25: Consulter les informations d'un jeu de données | F25: True | G25: Front-end | H25: Gestion des données & catalogue | J25: Structuration | K25: Pilier 1 – Connaissance & Caractérisation | L25: Administrateur expert data | M25: En tant qu'administrateur expert data, je veux consulter les informations d'un jeu de données afin d'en connaître le contenu et la source. | N25: Étant donné un jeu de données sans licence renseignée, Quand sa fiche est consultée, Alors la mention « licence non renseignée » est affichée (aucune valeur par défaut trompeuse). - Quand la fiche est consultée depuis le catalogue, Alors l'utilisateur voit les métadonnées de qualité associées (EPIC 2) si elles existent.
A26: US1bis.7-SC01 | B26: Visualisation du graphe de relations | C26: EPIC 1bis – Catalogage des données | D26: US1bis.7 | E26: Visualiser les relations entre indicateur et données sources | F26: True | G26: Front-end | H26: Gestion des données & catalogue | J26: Structuration | K26: Pilier 1 – Connaissance & Caractérisation | L26: Administrateur expert data | M26: En tant qu'administrateur expert data, je veux visualiser les relations entre un indicateur et ses données sources afin d'en comprendre la provenance. | N26: Étant donné un indicateur dérivé, Quand l'utilisateur ouvre sa page de relations, Alors il voit un graphe reliant l'indicateur à ses données sources et aux traitements intermédiaires. - Quand l'utilisateur clique sur un nœud du graphe (jeu de données source, traitement), Alors les métadonnées correspondantes sont affichées.
A27: US1bis.7-SC02 | B27: Précision de la période de calcul | C27: EPIC 1bis – Catalogage des données | D27: US1bis.7 | E27: Visualiser les relations entre indicateur et données sources | F27: True | G27: Front-end | H27: Gestion des données & catalogue | J27: Structuration | K27: Pilier 1 – Connaissance & Caractérisation | L27: Administrateur expert data | M27: En tant qu'administrateur expert data, je veux visualiser les relations entre un indicateur et ses données sources afin d'en comprendre la provenance. | N27: Étant donné un indicateur calculé sur des données historisées, Quand le graphe est affiché, Alors la version ou la période des données utilisées pour le calcul courant est précisée.
A28: US1bis.7-SC03 | B28: Absence de relations tracées | C28: EPIC 1bis – Catalogage des données | D28: US1bis.7 | E28: Visualiser les relations entre indicateur et données sources | F28: True | G28: Front-end | H28: Gestion des données & catalogue | J28: Structuration | K28: Pilier 1 – Connaissance & Caractérisation | L28: Administrateur expert data | M28: En tant qu'administrateur expert data, je veux visualiser les relations entre un indicateur et ses données sources afin d'en comprendre la provenance. | N28: Étant donné un indicateur sans dépendance déclarée, Quand la page est ouverte, Alors un message indique l'absence de relations tracées plutôt qu'un graphe vide. - Quand l'indicateur est recalculé sur de nouvelles données, Alors le graphe reflète les relations de la version de calcul la plus récente.
A29: US1bis.10-SC01 | B29: Alimentation automatique du catalogue | C29: EPIC 1bis – Catalogage des données | D29: US1bis.10 | E29: Alimenter automatiquement le catalogue lors des imports | F29: True | G29: Backend | H29: Gestion des données & catalogue | I29: US1.1 ; US1bis.1 | J29: Acquisition | K29: Pilier 1 – Connaissance & Caractérisation | L29: Administrateur expert data | M29: En tant qu'administrateur expert data, je veux alimenter automatiquement le catalogue lors des imports afin d'éviter les saisies manuelles. | N29: Étant donné un import de fichier réussi, Quand le traitement se termine, Alors une entrée de catalogue est créée ou mise à jour automatiquement, sans saisie manuelle.
A30: US1bis.10-SC02 | B30: Mise à jour sans doublon | C30: EPIC 1bis – Catalogage des données | D30: US1bis.10 | E30: Alimenter automatiquement le catalogue lors des imports | F30: True | G30: Backend | H30: Gestion des données & catalogue | I30: US1.1 ; US1bis.1 | J30: Acquisition | K30: Pilier 1 – Connaissance & Caractérisation | L30: Administrateur expert data | M30: En tant qu'administrateur expert data, je veux alimenter automatiquement le catalogue lors des imports afin d'éviter les saisies manuelles. | N30: Étant donné un jeu de données déjà catalogué, Quand un import le met à jour, Alors sa fiche de catalogue est actualisée (date de mise à jour, version courante) sans création de doublon.
A31: US1bis.10-SC03 | B31: Aucune entrée en cas d'échec | C31: EPIC 1bis – Catalogage des données | D31: US1bis.10 | E31: Alimenter automatiquement le catalogue lors des imports | F31: True | G31: Backend | H31: Gestion des données & catalogue | I31: US1.1 ; US1bis.1 | J31: Acquisition | K31: Pilier 1 – Connaissance & Caractérisation | L31: Administrateur expert data | M31: En tant qu'administrateur expert data, je veux alimenter automatiquement le catalogue lors des imports afin d'éviter les saisies manuelles. | N31: Étant donné un import en échec, Quand le traitement se termine, Alors aucune entrée de catalogue n'est créée, Et l'événement est tracé. - Quand une entrée est créée automatiquement, Alors les métadonnées minimales (nom, fournisseur, date de mise à jour) sont déduites de l'import et marquées « générées automatiquement ».
A32: US1bis.10-SC04 | B32: Échec partiel sans identifiant | C32: EPIC 1bis – Catalogage des données | D32: US1bis.10 | E32: Alimenter automatiquement le catalogue lors des imports | F32: True | G32: Backend | H32: Gestion des données & catalogue | I32: US1.1 ; US1bis.1 | J32: Acquisition | K32: Pilier 1 – Connaissance & Caractérisation | L32: Administrateur expert data | M32: En tant qu'administrateur expert data, je veux alimenter automatiquement le catalogue lors des imports afin d'éviter les saisies manuelles. | N32: Étant donné un import sans identifiant de jeu identifiable, Quand l'alimentation du catalogue est tentée, Alors l'import est signalé en échec partiel avec le motif.
A33: US1bis.12-SC01 | B33: Enregistrement d'un indicateur dérivé | C33: EPIC 1bis – Catalogage des données | D33: US1bis.12 | E33: Enregistrer un indicateur comme donnée dérivée | F33: True | G33: Front-end | H33: Gestion des données & catalogue | I33: US3.5 | J33: Structuration | K33: Pilier 1 – Connaissance & Caractérisation | L33: Administrateur expert data | M33: En tant qu'administrateur expert data, je veux enregistrer un indicateur comme donnée dérivée afin qu'il soit identifié comme tel dans le catalogue. | N33: Étant donné un indicateur défini dans le référentiel (US3.5), Quand il est enregistré dans le catalogue, Alors il apparaît avec le type « donnée dérivée », distinct des données sources. - Quand la fiche de l'indicateur est consultée, Alors elle indique qu'il s'agit d'une donnée dérivée et renvoie vers sa définition et sa méthode de calcul.
A34: US1bis.12-SC02 | B34: Refus sans donnée source | C34: EPIC 1bis – Catalogage des données | D34: US1bis.12 | E34: Enregistrer un indicateur comme donnée dérivée | F34: True | G34: Front-end | H34: Gestion des données & catalogue | I34: US3.5 | J34: Structuration | K34: Pilier 1 – Connaissance & Caractérisation | L34: Administrateur expert data | M34: En tant qu'administrateur expert data, je veux enregistrer un indicateur comme donnée dérivée afin qu'il soit identifié comme tel dans le catalogue. | N34: Étant donné un enregistrement sans lien vers une donnée source ou un traitement, Quand il est tenté, Alors il est refusé : tout indicateur dérivé référence au moins une donnée source ou un traitement.
A35: US1bis.12-SC03 | B35: Refus d'un indicateur non référencé | C35: EPIC 1bis – Catalogage des données | D35: US1bis.12 | E35: Enregistrer un indicateur comme donnée dérivée | F35: True | G35: Front-end | H35: Gestion des données & catalogue | I35: US3.5 | J35: Structuration | K35: Pilier 1 – Connaissance & Caractérisation | L35: Administrateur expert data | M35: En tant qu'administrateur expert data, je veux enregistrer un indicateur comme donnée dérivée afin qu'il soit identifié comme tel dans le catalogue. | N35: Étant donné un indicateur non défini dans le référentiel, Quand l'administrateur tente de l'enregistrer, Alors l'enregistrement est refusé avec un message renvoyant vers la définition de l'indicateur (US3.5). - Quand un indicateur dérivé est recalculé, Alors la version cataloguée est mise à jour, Et la traçabilité du calcul (date, version de la méthode, données utilisées) est conservée. ### EPIC 2 — Qualité des données
A36: US2.1-SC01 | B36: Détection de valeurs aberrantes | C36: EPIC 2 – Qualité des données | D36: US2.1 | E36: Détecter des valeurs aberrantes | F36: True | G36: Backend | H36: Suivi qualité & traçabilité | J36: Qualification | K36: Pilier 1 – Connaissance & Caractérisation (fondement) | L36: Administrateur expert data | M36: En tant qu'administrateur expert data, je veux détecter des valeurs aberrantes afin d'identifier les données à corriger. | N36: Étant donné un jeu de données avec des règles de contrôle définies (bornes min/max, plages attendues), Quand une valeur sort de la plage attendue, Alors l'anomalie est détectée et enregistrée avec le jeu de données, la ligne, la valeur et la règle violée. - Quand la détection est exécutée, Alors un rapport liste les valeurs aberrantes avec leur motif, sans modifier les données d'origine.
A37: US2.1-SC02 | B37: Exclusion d'une valeur erronée | C37: EPIC 2 – Qualité des données | D37: US2.1 | E37: Détecter des valeurs aberrantes | F37: True | G37: Backend | H37: Suivi qualité & traçabilité | J37: Qualification | K37: Pilier 1 – Connaissance & Caractérisation (fondement) | L37: Administrateur expert data | M37: En tant qu'administrateur expert data, je veux détecter des valeurs aberrantes afin d'identifier les données à corriger. | N37: Étant donné une valeur aberrante détectée et validée comme erronée par l'administrateur, Alors elle est exclue des traitements ou marquée non fiable, tout en restant disponible dans l'historique.
A38: US2.1-SC03 | B38: Blanchiment d'un faux positif | C38: EPIC 2 – Qualité des données | D38: US2.1 | E38: Détecter des valeurs aberrantes | F38: True | G38: Backend | H38: Suivi qualité & traçabilité | J38: Qualification | K38: Pilier 1 – Connaissance & Caractérisation (fondement) | L38: Administrateur expert data | M38: En tant qu'administrateur expert data, je veux détecter des valeurs aberrantes afin d'identifier les données à corriger. | N38: Étant donné une valeur signalée à tort (faux positif), Quand l'administrateur la blanchit, Alors le motif du blanchiment est documenté et tracé.
A39: US2.1-SC04 | B39: Jeu non contrôlé | C39: EPIC 2 – Qualité des données | D39: US2.1 | E39: Détecter des valeurs aberrantes | F39: True | G39: Backend | H39: Suivi qualité & traçabilité | J39: Qualification | K39: Pilier 1 – Connaissance & Caractérisation (fondement) | L39: Administrateur expert data | M39: En tant qu'administrateur expert data, je veux détecter des valeurs aberrantes afin d'identifier les données à corriger. | N39: Étant donné un jeu sans règles de détection configurées, Quand le contrôle est exécuté, Alors aucune valeur aberrante n'est signalée et le jeu est qualifié « non contrôlé ».
A40: US2.4-SC01 | B40: Calcul du taux de complétude | C40: EPIC 2 – Qualité des données | D40: US2.4 | E40: Calculer un taux de complétude | F40: True | G40: Backend | H40: Suivi qualité & traçabilité | J40: Qualification | K40: Pilier 1 – Connaissance & Caractérisation (fondement) | L40: Administrateur expert data | M40: En tant qu'administrateur expert data, je veux calculer un taux de complétude afin de mesurer la couverture des données. | N40: Étant donné un jeu de données avec des champs obligatoires définis, Quand le taux de complétude est calculé, Alors il correspond au pourcentage de valeurs renseignées sur les valeurs attendues, par champ et par jeu, Et le résultat est stocké comme métadonnée de qualité. - Quand un taux est calculé, Alors la période et la version du jeu de données utilisées pour le calcul sont précisées.
A41: US2.4-SC02 | B41: Marquage sous le seuil de complétude | C41: EPIC 2 – Qualité des données | D41: US2.4 | E41: Calculer un taux de complétude | F41: True | G41: Backend | H41: Suivi qualité & traçabilité | J41: Qualification | K41: Pilier 1 – Connaissance & Caractérisation (fondement) | L41: Administrateur expert data | M41: En tant qu'administrateur expert data, je veux calculer un taux de complétude afin de mesurer la couverture des données. | N41: Étant donné un seuil de complétude configuré (par défaut 95 %), Quand le taux calculé est inférieur au seuil, Alors le jeu est marqué comme sous le seuil, Et l'information est reportée sur sa fiche qualité. - Quand un jeu est mis à jour (nouvel import, corrections), Alors le taux est recalculé sur la dernière version, sans perte des taux historiques. - Quand le taux de complétude d'un jeu sert au calcul d'un indicateur (EPIC 4), Alors il est exploitable de façon automatisée (filtrage ou marquage du résultat).
A42: US2.5-SC01 | B42: Attribution d'une classe de fiabilité | C42: EPIC 2 – Qualité des données | D42: US2.5 | E42: Qualifier la fiabilité | F42: True | G42: Backend | H42: Suivi qualité & traçabilité | J42: Qualification | K42: Pilier 1 – Connaissance & Caractérisation (fondement) | L42: Administrateur expert data | M42: En tant qu'administrateur expert data, je veux qualifier la fiabilité afin d'évaluer la confiance à accorder aux données. | N42: Étant donné les critères de fiabilité définis (source, méthode de production, complétude, fréquence de mise à jour), Quand la fiabilité d'un jeu de données est évaluée, Alors une classe de fiabilité (élevée, moyenne, faible) lui est attribuée selon des règles documentées. - Quand une classe de fiabilité est attribuée, Alors la règle et les critères utilisés sont tracés.
A43: US2.5-SC02 | B43: Réévaluation de la fiabilité | C43: EPIC 2 – Qualité des données | D43: US2.5 | E43: Qualifier la fiabilité | F43: True | G43: Backend | H43: Suivi qualité & traçabilité | J43: Qualification | K43: Pilier 1 – Connaissance & Caractérisation (fondement) | L43: Administrateur expert data | M43: En tant qu'administrateur expert data, je veux qualifier la fiabilité afin d'évaluer la confiance à accorder aux données. | N43: Étant donné un jeu dont la qualité évolue (nouvel import, corrections), Quand la fiabilité est réévaluée, Alors la classe est recalculée, Et l'évolution est conservée dans l'historique des indicateurs de qualité.
...
